{"name": "test_login_nonexistent_user", "status": "failed", "statusDetails": {"message": "AssertionError: assert (404 == 404 and '{\"code\":404,... не найдена\"}' == 'Учетная запись не найдена'\n +  where 404 = <Response [404]>.status_code\n  \n  - Учетная запись не найдена\n  + {\"code\":404,\"message\":\"Учетная запись не найдена\"})", "trace": "self = <tests.test_login_courier.TestLoginCourier object at 0x0000017BF0168C90>\n\n    @allure.description('Проверка:попытка авторизации под несуществующим пользователем возвращает ошибку')\n    def test_login_nonexistent_user(self):\n        nonexistent_login_data = {\n            \"login\": \"nonexistent_user\",\n            \"password\": \"some_password\",\n        }\n    \n        response = requests.post(f'{url.SQOOTER_URL}/api/v1/courier/login', json=nonexistent_login_data)\n>       assert response.status_code == 404 and response.text == \"Учетная запись не найдена\"\nE       assert (404 == 404 and '{\"code\":404,... не найдена\"}' == 'Учетная запись не найдена'\nE        +  where 404 = <Response [404]>.status_code\nE         \nE         - Учетная запись не найдена\nE         + {\"code\":404,\"message\":\"Учетная запись не найдена\"})\n\ntests\\test_login_courier.py:40: AssertionError"}, "description": "Проверка:попытка авторизации под несуществующим пользователем возвращает ошибку", "start": 1722978245440, "stop": 1722978245599, "uuid": "0f0ac291-456d-4f53-91be-2a60608657f3", "historyId": "723ce2b188a8b83c6197faf747af910a", "testCaseId": "723ce2b188a8b83c6197faf747af910a", "fullName": "tests.test_login_courier.TestLoginCourier#test_login_nonexistent_user", "labels": [{"name": "parentSuite", "value": "tests"}, {"name": "suite", "value": "test_login_courier"}, {"name": "subSuite", "value": "TestLoginCourier"}, {"name": "host", "value": "LAPTOP-74V5TFPG"}, {"name": "thread", "value": "15128-MainThread"}, {"name": "framework", "value": "pytest"}, {"name": "language", "value": "cpython3"}, {"name": "package", "value": "tests.test_login_courier"}]}