{"name": "test_nonexistent_user", "status": "failed", "statusDetails": {"message": "AssertionError: assert (404 == 404 and '{\"code\":404,... не найдена\"}' == 'Учетная запись не найдена'\n +  where 404 = <Response [404]>.status_code\n  \n  - Учетная запись не найдена\n  + {\"code\":404,\"message\":\"Учетная запись не найдена\"})", "trace": "self = <tests.test_login_courier.TestLoginCourier object at 0x000001C095968D50>\n\n    @allure.description('Проверка:попытка авторизации под несуществующим пользователем возвращает ошибку')\n    def test_nonexistent_user(self):\n        response = requests.post(f'{url.SQOOTER_URL}/api/v1/courier/login',\n                                 json={\"login\": \"nonexistent_user\", \"password\": \"some_password\"})\n>       assert response.status_code == 404 and response.text == \"Учетная запись не найдена\"\nE       assert (404 == 404 and '{\"code\":404,... не найдена\"}' == 'Учетная запись не найдена'\nE        +  where 404 = <Response [404]>.status_code\nE         \nE         - Учетная запись не найдена\nE         + {\"code\":404,\"message\":\"Учетная запись не найдена\"})\n\ntests\\test_login_courier.py:30: AssertionError"}, "description": "Проверка:попытка авторизации под несуществующим пользователем возвращает ошибку", "start": 1722544240046, "stop": 1722544240230, "uuid": "9021b052-c682-4578-876a-7e00183b7cdd", "historyId": "18ccce41d57f13cf88ae432d36df33a1", "testCaseId": "18ccce41d57f13cf88ae432d36df33a1", "fullName": "tests.test_login_courier.TestLoginCourier#test_nonexistent_user", "labels": [{"name": "parentSuite", "value": "tests"}, {"name": "suite", "value": "test_login_courier"}, {"name": "subSuite", "value": "TestLoginCourier"}, {"name": "host", "value": "LAPTOP-74V5TFPG"}, {"name": "thread", "value": "17016-MainThread"}, {"name": "framework", "value": "pytest"}, {"name": "language", "value": "cpython3"}, {"name": "package", "value": "tests.test_login_courier"}]}